<?xml version="1.0" encoding="utf-8"?>
<robot name="MiniLiteV3">

  <link name="TORSO">
    <visual>
      <geometry>
        <mesh filename="../meshes/TORSO.dae" />
      </geometry>
    </visual>
    <collision>
      <geometry>
        <box size="0.234 0.184 0.08"/>
      </geometry>
    </collision>
  </link>

  <joint name="Torso2Inertia" type="fixed">
    <parent link="TORSO" />
    <child link="INERTIA" />
  </joint>

  <link name="INERTIA">
    <!-- <inertial>
      <origin xyz="0.046396 -0.0017592 0.028665" />
      <mass value="5.298" />
      <inertia ixx="0.0095569" ixy="5.9672E-05" ixz="9.3193E-05" iyy="0.014357" iyz="1.9063E-05" izz="0.01949" />
    </inertial> -->
    <inertial>
      <!-- <origin xyz="0.004098 -0.000663 -0.002069" /> -->
      <origin xyz="-0.02 -0.000663 -0.002069" />
      <mass value="6.130" />
      <!-- <mass value="4.130" /> -->
      <inertia ixx="0.016982120" ixy="2.1294E-05" ixz="6.0763E-05" iyy="0.030466501" iyz="1.7968E-05" izz="0.042609956" />
    </inertial>
  </link>

  <joint name="FL_HipX_joint" type="revolute">
    <origin xyz="0.1745 0.062 0" />
    <parent link="TORSO" />
    <child link="FL_HIP" />
    <axis xyz="1 0 0" />
    <dynamics damping="0.01" friction="0.03"/>
    <limit lower="-0.523" upper="0.523" effort="24" velocity="25" />
  </joint>
  
  <link name="FL_HIP">
    <inertial>
      <origin xyz="-0.0047 -0.0091 -0.0018" />
      <mass value="0.428" />
      <inertia ixx="0.00014538" ixy="8.1579E-07" ixz="-1.264E-05" iyy="0.00024024" iyz="1.3443E-06" izz="0.00013038" />
    </inertial>
    <visual>
      <geometry>
        <mesh filename="../meshes/FL_HIP.dae" />
      </geometry>
    </visual>
  </link>
  
  <joint name="FL_hip_fixed" type="fixed" dont_collapse="true">
    <origin rpy="0 0 0" xyz="0 0.08 0"/>
    <parent link="FL_HIP"/>
    <child link="FL_shoulder"/>
  </joint>
  <link name="FL_shoulder">
    <visual>
      <origin rpy="1.57079632679 0 0" xyz="0 0 0"/>
      <geometry>
        <cylinder length="0.02" radius="0.04"/>
      </geometry>
    </visual>
    <collision>
      <origin rpy="1.57079632679 0 0" xyz="0 0 0"/>
      <geometry>
        <cylinder length="0.02" radius="0.04"/>
      </geometry>
    </collision>
    <inertial>
      <mass value="0.0001"/>
      <inertia ixx="9.6e-06" ixy="0.0" ixz="0.0" iyy="9.6e-06" iyz="0.0" izz="9.6e-06"/>
    </inertial>
  </link>

  <joint name="FL_HipY_joint" type="revolute">
    <origin xyz="0 0.0875 0" />
    <parent link="FL_HIP" />
    <child link="FL_THIGH" />
    <axis xyz="0 1 0" />
    <dynamics damping="0.01" friction="0.03"/>
    <limit lower="-0.314" upper="2.67" effort="24" velocity="25" />
  </joint>
  
  <link name="FL_THIGH">
    <inertial>
      <origin xyz="-0.00523 -0.0216 -0.0273" />
      <mass value="0.61" />
      <inertia ixx="0.001" ixy="-2.5E-06" ixz="-1.12E-04" iyy="0.00116" iyz="3.75E-07" izz="2.68E-04" />
    </inertial>
    <visual>
      <geometry>
        <mesh filename="../meshes/L_THIGH.dae" />
      </geometry>
    </visual>
    <collision>
      <origin xyz="0 0 -0.08"/>
      <geometry>
        <box size="0.02 0.02 0.16"/>
      </geometry>
    </collision>
  </link>

  <joint name="FL_Knee_joint" type="revolute">
    <origin xyz="0 0 -0.20" />
    <parent link="FL_THIGH" />
    <child link="FL_SHANK" />
    <axis xyz="0 1 0" />
    <dynamics damping="0.01" friction="0.03"/>
    <limit lower="-2.792" upper="-0.524" effort="36.7" velocity="17" />
  </joint>

  <link name="FL_SHANK">
    <inertial>
      <origin xyz="0.00585 -8.732E-07 -0.12" />
      <mass value="0.115" />
      <inertia ixx="6.68E-04" ixy="-1.24E-08" ixz="6.91E-06" iyy="6.86E-04" iyz="5.65E-09" izz="3.155E-05" />
    </inertial>
    <visual>
      <geometry>
        <mesh filename="../meshes/SHANK.dae" />
      </geometry>
    </visual>
    <collision>
      <origin xyz="0 0 -0.09"/>
      <geometry>
        <box size="0.02 0.02 0.18"/>
      </geometry>
    </collision>
  </link>

  <joint name="FL_Ankle" type="fixed" dont_collapse="true">
    <origin xyz="0 0 -0.21"/>
    <parent link="FL_SHANK" />
    <child link="FL_FOOT" />
  </joint>

  <link name="FL_FOOT">
    <inertial>
      <mass value="0.06" />
      <inertia ixx="1E-6" ixy="0" ixz="0" iyy="1E-6" iyz="0" izz="1E-6" />
    </inertial>
    <collision>
      <geometry>
        <sphere radius="0.02"/>
      </geometry>
    </collision>
  </link>

  <joint name="FR_HipX_joint" type="revolute">
    <origin xyz="0.1745 -0.062 0" />
    <parent link="TORSO" />
    <child link="FR_HIP" />
    <axis xyz="1 0 0" />
    <dynamics damping="0.01" friction="0.03"/>
    <limit lower="-0.523" upper="0.523" effort="24" velocity="25" />
  </joint>

  <link name="FR_HIP">
    <inertial>
      <origin xyz="-0.0047 0.0091 -0.0018" />
      <mass value="0.428" />
      <inertia ixx="0.00014538" ixy="-8.1551E-07" ixz="-1.2639E-05" iyy="0.00024024" iyz="-1.3441E-06" izz="0.00013038" />
    </inertial>
    <visual>
      <geometry>
        <mesh filename="../meshes/FR_HIP.dae" />
      </geometry>
    </visual>
  </link>

  <joint name="FR_hip_fixed" type="fixed" dont_collapse="true">
    <origin rpy="0 0 0" xyz="0 -0.08 0"/>
    <parent link="FR_HIP"/>
    <child link="FR_shoulder"/>
  </joint>
  <link name="FR_shoulder">
    <visual>
      <origin rpy="1.57079632679 0 0" xyz="0 0 0"/>
      <geometry>
        <cylinder length="0.02" radius="0.04"/>
      </geometry>
    </visual>
    <collision>
      <origin rpy="1.57079632679 0 0" xyz="0 0 0"/>
      <geometry>
        <cylinder length="0.02" radius="0.04"/>
      </geometry>
    </collision>
    <inertial>
      <mass value="0.0001"/>
      <inertia ixx="9.6e-06" ixy="0.0" ixz="0.0" iyy="9.6e-06" iyz="0.0" izz="9.6e-06"/>
    </inertial>
  </link>

  <joint name="FR_HipY_joint" type="revolute">
    <origin xyz="0 -0.0875 0" />
    <parent link="FR_HIP" />
    <child link="FR_THIGH" />
    <axis xyz="0 1 0" />
    <dynamics damping="0.01" friction="0.03"/>
    <limit lower="-0.314" upper="2.67" effort="24" velocity="25" />
  </joint>

  <link name="FR_THIGH">
    <inertial>
      <origin xyz="-0.00523 0.0216 -0.0273" />
      <mass value="0.61" />
      <inertia ixx="0.001" ixy="2.5E-06" ixz="-1.12E-04" iyy="0.00116" iyz="-3.75E-07" izz="2.68E-04" />
    </inertial>
    <visual>
      <geometry>
        <mesh filename="../meshes/R_THIGH.dae" />
      </geometry>
    </visual>
    <collision>
      <origin xyz="0 0 -0.08"/>
      <geometry>
        <box size="0.02 0.02 0.16"/>
      </geometry>
    </collision>
  </link>

  <joint name="FR_Knee_joint" type="revolute">
    <origin xyz="0 0 -0.20" />
    <parent link="FR_THIGH" />
    <child link="FR_SHANK" />
    <axis xyz="0 1 0" />
    <dynamics damping="0.01" friction="0.03"/>
    <limit lower="-2.792" upper="-0.524" effort="36.7" velocity="17" />
  </joint>

  <link name="FR_SHANK">
    <inertial>
      <origin xyz="0.00585 -8.732E-07 -0.12" />
      <mass value="0.115" />
      <inertia ixx="6.68E-04" ixy="-1.24E-08" ixz="6.91E-06" iyy="6.86E-04" iyz="5.65E-09" izz="3.155E-05" />
    </inertial>
    <visual>
      <geometry>
        <mesh filename="../meshes/SHANK.dae" />
      </geometry>
    </visual>
    <collision>
      <origin xyz="0 0 -0.09"/>
      <geometry>
        <box size="0.02 0.02 0.18"/>
      </geometry>
    </collision>
  </link>

  <joint name="FR_Ankle" type="fixed" dont_collapse="true">
    <origin xyz="0 0 -0.21"/>
    <parent link="FR_SHANK" />
    <child link="FR_FOOT" />
  </joint>

  <link name="FR_FOOT">
    <inertial>
      <mass value="0.06" />
      <inertia ixx="1E-6" ixy="0" ixz="0" iyy="1E-6" iyz="0" izz="1E-6" />
    </inertial>
    <collision>
      <geometry>
        <sphere radius="0.02"/> 
        <!-- 0.13 -->
      </geometry>
    </collision>
  </link>

  <joint name="HL_HipX_joint" type="revolute">
    <origin xyz="-0.1745 0.062 0" />
    <parent link="TORSO" />
    <child link="HL_HIP" />
    <axis xyz="1 0 0" />
    <dynamics damping="0.01" friction="0.03"/>
    <limit lower="-0.523" upper="0.523" effort="24" velocity="25" />
  </joint>

  <link name="HL_HIP">
    <inertial>
      <origin xyz="0.0047 -0.0091 -0.0018" />
      <mass value="0.428" />
      <inertia ixx="0.00014538" ixy="-8.1585E-07" ixz="1.2639E-05" iyy="0.00024024" iyz="1.3444E-06" izz="0.00013038" />
    </inertial>
    <visual>
      <geometry>
        <mesh filename="../meshes/HL_HIP.dae" />
      </geometry>
    </visual>
  </link>

  <joint name="HL_hip_fixed" type="fixed" dont_collapse="true">
    <origin rpy="0 0 0" xyz="0 0.08 0"/>
    <parent link="HL_HIP"/>
    <child link="HL_shoulder"/>
  </joint>
  <link name="HL_shoulder">
    <visual>
      <origin rpy="1.57079632679 0 0" xyz="0 0 0"/>
      <geometry>
        <cylinder length="0.02" radius="0.04"/>
      </geometry>
    </visual>
    <collision>
      <origin rpy="1.57079632679 0 0" xyz="0 0 0"/>
      <geometry>
        <cylinder length="0.02" radius="0.04"/>
      </geometry>
    </collision>
    <inertial>
      <mass value="0.0001"/>
      <inertia ixx="9.6e-06" ixy="0.0" ixz="0.0" iyy="9.6e-06" iyz="0.0" izz="9.6e-06"/>
    </inertial>
  </link>

  <joint name="HL_HipY_joint" type="revolute">
    <origin xyz="0 0.0875 0" />
    <parent link="HL_HIP" />
    <child link="HL_THIGH" />
    <axis xyz="0 1 0" />
    <dynamics damping="0.01" friction="0.03"/>
    <limit lower="-0.314" upper="2.67" effort="24" velocity="25" />
  </joint>

  <link name="HL_THIGH">
    <inertial>
      <origin xyz="-0.00523 -0.0216 -0.0273" />
      <mass value="0.61" />
      <inertia ixx="0.001" ixy="-2.5E-06" ixz="-1.12E-04" iyy="0.00116" iyz="3.75E-07" izz="2.68E-04" />
    </inertial>
    <visual>
      <geometry>
        <mesh filename="../meshes/L_THIGH.dae" />
      </geometry>
    </visual>
    <collision>
      <origin xyz="0 0 -0.08"/>
      <geometry>
        <box size="0.02 0.02 0.16"/>
      </geometry>
    </collision>
  </link>

  <link name="HL_SHANK">
    <inertial>
      <origin xyz="0.00585 -8.732E-07 -0.12" />
      <mass value="0.115" />
      <inertia ixx="6.68E-04" ixy="-1.24E-08" ixz="6.91E-06" iyy="6.86E-04" iyz="5.65E-09" izz="3.155E-05" />
    </inertial>
    <visual>
      <geometry>
        <mesh filename="../meshes/SHANK.dae" />
      </geometry>
    </visual>
    <collision>
      <origin xyz="0 0 -0.09"/>
      <geometry>
        <box size="0.02 0.02 0.18"/>
      </geometry>
    </collision>
  </link>

  <joint name="HL_Knee_joint" type="revolute">
    <origin xyz="0 0 -0.20" />
    <parent link="HL_THIGH" />
    <child link="HL_SHANK" />
    <axis xyz="0 1 0" />
    <dynamics damping="0.01" friction="0.03"/>
    <limit lower="-2.792" upper="-0.524" effort="36.7" velocity="17" />
  </joint>

  <link name="HL_FOOT">
    <inertial>
      <mass value="0.06" />
      <inertia ixx="1E-6" ixy="0" ixz="0" iyy="1E-6" iyz="0" izz="1E-6" />
    </inertial>
    <collision>
      <geometry>
        <sphere radius="0.02"/>
      </geometry>
    </collision>
  </link>

  <joint name="HL_Ankle" type="fixed" dont_collapse="true">
    <origin xyz="0 0 -0.21"/>
    <parent link="HL_SHANK" />
    <child link="HL_FOOT" />
  </joint>

  <joint name="HR_HipX_joint" type="revolute">
    <origin xyz="-0.1745 -0.062 0" />
    <parent link="TORSO" />
    <child link="HR_HIP" />
    <axis xyz="1 0 0" />
    <dynamics damping="0.01" friction="0.03"/>
    <limit lower="-0.523" upper="0.523" effort="24" velocity="25" />
  </joint>

  <link name="HR_HIP">
    <inertial>
      <origin xyz="0.0047 0.0091 -0.0018" />
      <mass value="0.428" />
      <inertia ixx="0.00014538" ixy="8.1545E-07" ixz="1.2639E-05" iyy="0.00024024" iyz="-1.344E-06" izz="0.00013038" />
    </inertial>
    <visual>
      <geometry>
        <mesh filename="../meshes/HR_HIP.dae" />
      </geometry>
    </visual>
  </link>

  <joint name="HR_hip_fixed" type="fixed" dont_collapse="true">
    <origin rpy="0 0 0" xyz="0 -0.08 0"/>
    <parent link="HR_HIP"/>
    <child link="HR_shoulder"/>
  </joint>
  <link name="HR_shoulder">
    <visual>
      <origin rpy="1.57079632679 0 0" xyz="0 0 0"/>
      <geometry>
        <cylinder length="0.02" radius="0.04"/>
      </geometry>
    </visual>
    <collision>
      <origin rpy="1.57079632679 0 0" xyz="0 0 0"/>
      <geometry>
        <cylinder length="0.02" radius="0.04"/>
      </geometry>
    </collision>
    <inertial>
      <mass value="0.0001"/>
      <inertia ixx="9.6e-06" ixy="0.0" ixz="0.0" iyy="9.6e-06" iyz="0.0" izz="9.6e-06"/>
    </inertial>
  </link>

  <joint name="HR_HipY_joint" type="revolute">
    <origin xyz="0 -0.0875 0" />
    <parent link="HR_HIP" />
    <child link="HR_THIGH" />
    <axis xyz="0 1 0" />
    <dynamics damping="0.01" friction="0.03"/>
    <limit lower="-0.314" upper="2.67" effort="24" velocity="25" />
  </joint>

  <link name="HR_THIGH">
    <inertial>
      <origin xyz="-0.00523 0.0216 -0.0273" />
      <mass value="0.61" />
      <inertia ixx="0.001" ixy="2.5E-06" ixz="-1.12E-04" iyy="0.00116" iyz="-3.75E-07" izz="2.68E-04" />
    </inertial>
    <visual>
      <geometry>
        <mesh filename="../meshes/R_THIGH.dae" />
      </geometry>
    </visual>
    <collision>
      <origin xyz="0 0 -0.08"/>
      <geometry>
        <box size="0.02 0.02 0.16"/>
      </geometry>
    </collision>
  </link>

  <joint name="HR_Knee_joint" type="revolute">
    <origin xyz="0 0 -0.20" />
    <parent link="HR_THIGH" />
    <child link="HR_SHANK" />
    <axis xyz="0 1 0" />
    <dynamics damping="0.01" friction="0.03"/>
    <limit lower="-2.792" upper="-0.524" effort="36.7" velocity="17" />
  </joint>

  <link name="HR_SHANK">
    <inertial>
      <origin xyz="0.00585 -8.732E-07 -0.12" />
      <mass value="0.115" />
      <inertia ixx="6.68E-04" ixy="-1.24E-08" ixz="6.91E-06" iyy="6.86E-04" iyz="5.65E-09" izz="3.155E-05" />
    </inertial>
    <visual>
      <geometry>
        <mesh filename="../meshes/SHANK.dae" />
      </geometry>
    </visual>
    <collision>
      <origin xyz="0 0 -0.09"/>
      <geometry>
        <box size="0.02 0.02 0.18"/>
      </geometry>
    </collision>
  </link>

  <joint name="HR_Ankle" type="fixed" dont_collapse="true">
    <origin xyz="0 0 -0.21"/>
    <parent link="HR_SHANK" />
    <child link="HR_FOOT" />
  </joint>

  <link name="HR_FOOT">
    <!-- <visual>
      <origin rpy="0 0 0" xyz="0 0 0"/>
      <geometry>
        <sphere radius="0.02"/>
      </geometry>
    </visual> -->
    <inertial>
      <mass value="0.06" />
      <inertia ixx="1E-6" ixy="0" ixz="0" iyy="1E-6" iyz="0" izz="1E-6" />
    </inertial>
    <collision>
      <geometry>
        <sphere radius="0.02"/>
      </geometry>
    </collision>
  </link>

</robot>
